<?xml version="1.1"?>
<robot name="pybullet_reacher_robot">
  <link name="world"/>

  <joint name="fixed" type="fixed">
    <parent link="world"/>
    <child link="link0"/>
  </joint>

<link name="link0">
  <visual>
    <origin xyz="0 0 .025" rpy="0 1.570796 0" />
    <geometry>
      <cylinder length="0.05" radius="0.03"/>
    </geometry>
    <material name="yellow">
      <color rgba=".8 .8 .0 1"/>
    </material>
  </visual>

  <collision>
    <origin xyz="0 0 .025" rpy="1.570796 0 0" />
    <geometry>
      <cylinder length="0.05" radius="0.03"/>
    </geometry>
  </collision>

  <inertial>
    <origin xyz="0 0 .025" rpy="0 0 0" />
    <mass value="1"/>
    <inertia ixx="0.0" ixy="0.0" ixz="0.0" iyy="0.0" iyz="0.0" izz="0.0"/>
  </inertial> -->



</link>


<!-- joint between 0 and 1 -->
<joint name="joint1" type="revolute">
  <parent link="link0"/>
  <child link="link1"/>
  <origin xyz="0 0 .025" rpy="0 0 0"/>
  <axis xyz="1 0 0"/>
  <limit effort="10" lower="0" upper="3.14" velocity="0"/>
</joint>


<!-- link1 : Pan1 -->
<link name="link1">
  <visual>
    <origin xyz="0 0.5 0" rpy="1.570796 0 0" />
    <geometry>
      <cylinder length="1" radius="0.015"/>
    </geometry>
    <material name="blue">
      <color rgba=".0 .0 .8 1"/>
    </material>
  </visual>

  <collision>
    <origin xyz="0 0.5 0" rpy="1.570796 0 0" />
    <geometry>
      <cylinder length="1" radius="0.015"/>
    </geometry>
  </collision> 

  <inertial>
    <origin xyz="0 0.5 0" rpy="0 0 0" />
    <mass value="1"/>
    <inertia ixx="0.0" ixy="0.0" ixz="0.0" iyy="0.0" iyz="0.0" izz="0.0"/>
  </inertial>	-->


</link>


<!-- joint between 1 and 2 -->
<joint name="joint2" type="revolute">
  <parent link="link1"/>
  <child link="link2"/>
  <origin xyz="0 1 0" rpy="0 0 0"/>
  <axis xyz="1 0 0"/>
  <limit effort="10" lower="-3.14" upper="0" velocity="10"/>
</joint> 


<!-- link3 : pan2 -->
<link name="link2">
  <visual>
    <origin xyz="0 0.5 0" rpy="1.570796 0 0" />
    <geometry>
      <cylinder length="1" radius="0.015"/>
    </geometry>
    <material name="sky">
      <color rgba="0 .8 .8 1"/>
    </material>
  </visual>


  <collision>
    <origin xyz="0 0.5 0" rpy="1.570796 0 0" />
    <geometry>
      <cylinder length="1" radius="0.015"/>
    </geometry>
  </collision> 

  <inertial>
    <origin xyz="0 0.5 0" rpy="0 0 0" />
    <mass value="1"/>
    <inertia ixx="0.0" ixy="0.0" ixz="0.0" iyy="0.0" iyz="0.0" izz="0.0"/>
  </inertial>	-->
</link> 


<!-- joint between 2 and 3 -->
<joint name="joint3" type="revolute">
  <parent link="link2"/>
  <child link="link3"/>
  <origin xyz="0 1 0" rpy="0 0 0"/>
  <axis xyz="1 0 0"/>
  <limit effort="10" lower="-3.14" upper="0" velocity="10"/>
</joint> 


<!-- link3 -->
<link name="link3">
  <visual>
    <origin xyz="0 0.25 0" rpy="1.570796 0 0" />
    <geometry>
      <cylinder length="0.5" radius="0.015"/>
    </geometry>
    <material name="red">
      <color rgba=".9 0 0 1"/>
    </material>
  </visual>

  <collision>
    <origin xyz="0 0.25 0" rpy="1.570796 0 0" />
    <geometry>
      <cylinder length="0.5" radius="0.015"/>
    </geometry>
  </collision> 

  <inertial>
    <origin xyz="0 0.25 0" rpy="0 0 0" />
    <mass value="1"/>
    <inertia ixx="0.0" ixy="0.0" ixz="0.0" iyy="0.0" iyz="0.0" izz="0.0"/>
  </inertial>	-->


</link> 
<!-- joint between 3 and 4 -->
<joint name="joint4" type="revolute">
  <parent link="link3"/>
  <child link="link4"/>
  <origin xyz="0 0.5 0" rpy="0 0 0"/>
  <axis xyz="1 0 0"/>
  <limit effort="10" lower="0" upper="0" velocity="10"/>
</joint> 


<!-- link5 : end-effector -->
<link name="link4">
  <visual>
    <origin xyz="0 0 0" rpy="1.570796 0 0" />
    <geometry>
      <sphere radius="0.02"/>
    </geometry>
    <material name="red">
      <color rgba=".9 0 0 1"/>
    </material>
  </visual>

  <collision>
    <origin xyz="0 0 0" rpy="1.570796 0 0" />
    <geometry>
      <sphere radius="0.015"/>
    </geometry>
  </collision> 

  <inertial>
    <origin xyz="0 0 0" rpy="0 0 0" />
    <mass value="1"/>
    <inertia ixx="0.0" ixy="0.0" ixz="0.0" iyy="0.0" iyz="0.0" izz="0.0"/>
  </inertial>	-->
</link> 
</robot>

